[30/Jun/2017 16:40:07] ERROR [django.request:135] Internal Server Error: /restaurantes/api/restaurants/
Traceback (most recent call last):
  File "/home/pablo/Facultad/SSBW/SSBW/Entrega1/lib/python3.5/site-packages/django/core/handlers/exception.py", line 41, in inner
    response = get_response(request)
  File "/home/pablo/Facultad/SSBW/SSBW/Entrega1/lib/python3.5/site-packages/django/core/handlers/base.py", line 187, in _get_response
    response = self.process_exception_by_middleware(e, request)
  File "/home/pablo/Facultad/SSBW/SSBW/Entrega1/lib/python3.5/site-packages/django/core/handlers/base.py", line 185, in _get_response
    response = wrapped_callback(request, *callback_args, **callback_kwargs)
  File "/home/pablo/Facultad/SSBW/SSBW/Entrega1/lib/python3.5/site-packages/django/views/decorators/csrf.py", line 58, in wrapped_view
    return view_func(*args, **kwargs)
  File "/home/pablo/Facultad/SSBW/SSBW/Entrega1/lib/python3.5/site-packages/rest_framework/viewsets.py", line 86, in view
    return self.dispatch(request, *args, **kwargs)
  File "/home/pablo/Facultad/SSBW/SSBW/Entrega1/lib/python3.5/site-packages/rest_framework/views.py", line 489, in dispatch
    response = self.handle_exception(exc)
  File "/home/pablo/Facultad/SSBW/SSBW/Entrega1/lib/python3.5/site-packages/rest_framework/views.py", line 449, in handle_exception
    self.raise_uncaught_exception(exc)
  File "/home/pablo/Facultad/SSBW/SSBW/Entrega1/lib/python3.5/site-packages/rest_framework/views.py", line 486, in dispatch
    response = handler(request, *args, **kwargs)
  File "/home/pablo/Facultad/SSBW/SSBW/Entrega1/lib/python3.5/site-packages/rest_framework/mixins.py", line 48, in list
    return Response(serializer.data)
  File "/home/pablo/Facultad/SSBW/SSBW/Entrega1/lib/python3.5/site-packages/rest_framework/serializers.py", line 739, in data
    ret = super(ListSerializer, self).data
  File "/home/pablo/Facultad/SSBW/SSBW/Entrega1/lib/python3.5/site-packages/rest_framework/serializers.py", line 263, in data
    self._data = self.to_representation(self.instance)
  File "/home/pablo/Facultad/SSBW/SSBW/Entrega1/lib/python3.5/site-packages/rest_framework/serializers.py", line 657, in to_representation
    self.child.to_representation(item) for item in iterable
  File "/home/pablo/Facultad/SSBW/SSBW/Entrega1/lib/python3.5/site-packages/rest_framework/serializers.py", line 657, in <listcomp>
    self.child.to_representation(item) for item in iterable
  File "/home/pablo/Facultad/SSBW/SSBW/Entrega1/lib/python3.5/site-packages/rest_framework/serializers.py", line 501, in to_representation
    ret[field.field_name] = field.to_representation(attribute)
  File "/home/pablo/Facultad/SSBW/SSBW/Entrega1/lib/python3.5/site-packages/rest_framework/serializers.py", line 501, in to_representation
    ret[field.field_name] = field.to_representation(attribute)
  File "/home/pablo/Facultad/SSBW/SSBW/Entrega1/lib/python3.5/site-packages/rest_framework/fields.py", line 913, in to_representation
    return int(value)
ValueError: invalid literal for int() with base 10: ''
[30/Jun/2017 16:40:07] ERROR [django.server:124] "GET /restaurantes/api/restaurants/ HTTP/1.1" 500 19165
